<?xml version="1.0"?>

<robot name="pingpang_robot" xmlns:xacro="http://www.ros.org/wiki/xacro">
  
  <xacro:include filename="$(find pingpang_gazebo)/urdf/accessories/stereo_camera.urdf.xacro"/> 

  <xacro:include filename="$(find pingpang_gazebo)/urdf/transmission_effort.xacro"/>

  <xacro:include filename="$(find ur_description)/urdf/ur10.urdf.xacro" />

  <xacro:ur10_robot prefix="ur_" joint_limited="false"/>
 
 <!-- Degree-to-radian conversions -->
  <xacro:property name="degrees_45" value="0.785398163"/>
  <xacro:property name="degrees_90" value="1.57079633"/>
  
  <xacro:property name="M_PI" value="3.14159"/>

  <xacro:property name="BASE_LINE" value="0.14"/>
  <xacro:property name="OPTICAL_X" value="0"/>
  <xacro:property name="OPTICAL_Y" value="0"/>
  <xacro:property name="OPTICAL_Z" value="0"/>
  <xacro:property name="OPTICAL_A" value="0"/>
  <xacro:property name="OPTICAL_B" value="0"/>
  <xacro:property name="OPTICAL_C" value="0"/>
  <xacro:property name="PIXEL_WIDTH" value="640"/>
  <xacro:property name="PIXEL_HEIGHT" value="480"/>
  <xacro:property name="CAMERA_RATE" value="30.0"/>
  <xacro:property name="CAMERA_FOV" value="1.3962634"/>
  <xacro:property name="CAMERA_DISTORTION_K1" value="0"/>
  <xacro:property name="CAMERA_DISTORTION_K2" value="0"/>
  <xacro:property name="CAMERA_DISTORTION_K3" value="0"/>
  <xacro:property name="CAMERA_DISTORTION_T1" value="0"/>
  <xacro:property name="CAMERA_DISTORTION_T2" value="0"/> 

 <!-- User define Stereo_Cam1 -->
  <xacro:property name="STEREO_CAM_X" value="0.05"/>
  <xacro:property name="STEREO_CAM_Y" value="0.07"/>
  <xacro:property name="STEREO_CAM_Z" value="0.015"/>
  <xacro:property name="STEREO_CAM_A" value="0"/>
  <xacro:property name="STEREO_CAM_B" value="0"/>
  <xacro:property name="STEREO_CAM_C" value="0"/>


  <!-- stereo_camera_model&param_macro -->
  <xacro:stereo_camera prefix="basler"/>

  <!-- stereo_camera1_frame_joint -->
  <joint name="stereo_camera_frame_joint" type="fixed">
    <origin xyz="${STEREO_CAM_X} ${STEREO_CAM_Y} ${STEREO_CAM_Z}" rpy="${STEREO_CAM_A} ${STEREO_CAM_B} ${STEREO_CAM_C}" />
    <parent link="base_link"/>
    <child link="stereo_basler"/>
  </joint> 


  <link name="world"/>

  <joint name="world_joint_1" type="fixed">
    <parent link="world" />
    <child link = "ur_base_link" />
    <origin xyz="1.0 1.0 1.0" rpy="0.0 0.0 0.0" />
  </joint>

  <link name="base_link" >
    <visual> 
      <geometry>
         <box size="0.1 0.1 0.01"/>
      </geometry>
    </visual>

    <collision>
      <geometry>
         <box size="0.1 0.1 0.01"/>
      </geometry>
    </collision>

    <inertial>
      <mass value="0.1" />
      <inertia ixx="0.1" ixy="0.0" ixz="0.0"
        iyy="0.1" iyz="0.0"
        izz="0.1" />
    </inertial>
  </link>

  <joint name="world_joint" type="fixed">
    <origin xyz="0.8 3 1.5" rpy="0 ${degrees_90/8} ${-degrees_90}" />
    <parent link="world" />
    <child link = "base_link" />
  </joint>

  <link name="move_link" >
    <visual> 
      <geometry>
         <box size="2 0.5 0.6"/>
      </geometry>
    </visual>
    <collision>
      <geometry>
         <box size="2 0.5 0.6"/>
      </geometry>
    </collision>
    <inertial>
      <mass value="0.1" />
      <inertia ixx="0.1" ixy="0.0" ixz="0.0"
        iyy="0.1" iyz="0.0"
        izz="0.1" />
    </inertial>
  </link>
   
  <joint name="move_joint" type="fixed">
    <origin xyz="0.8 3 0.3" rpy="0 0 0" />
    <parent link="world" />
    <child link = "move_link" />
  </joint>


  <link name="move_1_link" >
    <visual> 
      <geometry>
         <box size="0.02 0.02 0.6"/>
      </geometry>
      <material name="body"/>
    </visual>
    <collision>
      <geometry>
         <box size="0.02 0.02 0.6"/>
      </geometry>
    </collision>
    <inertial>
      <mass value="0.1" />
      <inertia ixx="0.1" ixy="0.0" ixz="0.0"
        iyy="0.1" iyz="0.0"
        izz="0.1" />
    </inertial>
  </link> 

  <joint name="move_1_joint" type="prismatic">
    <origin xyz="0 0 0.6" rpy="0 0 0" />
    <axis xyz="1 0 0"/>
    <parent link="move_link" />
    <child link = "move_1_link" />
    <limit effort="1000.0" lower="-3" upper="3" velocity="0.5"/>
  </joint>

  <link name="move_2_link" >
    <visual> 
      <geometry>
         <box size="0.02 0.02 0.2"/>
      </geometry>
      <material name="body"/>
    </visual>
    <collision>
      <geometry>
         <box size="0.02 0.02 0.2"/>
      </geometry>
    </collision>
    <inertial>
      <mass value="0.1" />
      <inertia ixx="0.1" ixy="0.0" ixz="0.0"
        iyy="0.1" iyz="0.0"
        izz="0.1" />
    </inertial>
  </link> 

  <joint name="move_2_joint" type="prismatic">
    <origin xyz="0 -0.02 0" rpy="0 ${degrees_90} 0" />
    <axis xyz="1 0 0"/>
    <parent link="move_1_link" />
    <child link = "move_2_link" />
    <limit effort="1000.0" lower="-0.2" upper="0.2" velocity="0.5"/>
  </joint>

  <link name="move_3_link" >
    <visual> 
      <geometry>
         <box size="0.2 0.01 0.2"/>
      </geometry>
      <material name="body"/>
    </visual>
    <collision>
      <geometry>
         <box size="0.2 0.01 0.2"/>
      </geometry>
    </collision>
    <inertial>
      <mass value="0.1" />
      <inertia ixx="0.1" ixy="0.0" ixz="0.0"
        iyy="0.1" iyz="0.0"
        izz="0.1" />
    </inertial>
  </link> 

  <joint name="move_3_joint" type="prismatic">
    <origin xyz="0 -0.015 0" rpy="0 0 0" />
    <axis xyz="0 1 0"/>
    <parent link="move_2_link" />
    <child link = "move_3_link" />
    <limit effort="1000.0" lower="-3" upper="3" velocity="0.5"/>
  </joint>  

  <gazebo reference="move_1_link">
    <material>Gazebo/Red</material>
  </gazebo>

  <gazebo reference="move_2_link">
    <material>Gazebo/Blue</material>
  </gazebo>

  <gazebo reference="move_3_link">
    <material>Gazebo/Red</material>
  </gazebo>

  <gazebo>
    <plugin filename="libgazebo_ros_control.so" name="gazebo_ros_control">
      <controlPeriod>0.001</controlPeriod>
    </plugin>
  </gazebo>

</robot>
