<?xml version="1.0" ?>
<!-- =================================================================================== -->
<!-- |    This document was autogenerated by xacro from pingpang.urdf.xacro            | -->
<!-- |    EDITING THIS FILE BY HAND IS NOT RECOMMENDED                                 | -->
<!-- =================================================================================== -->
<robot name="pingpang_robot" xmlns:xacro="http://www.ros.org/wiki/xacro">
  <transmission name="trans_1">
    <type>transmission_interface/SimpleTransmission</type>
    <joint name="move_1_joint">
      <hardwareInterface>EffortJointInterface</hardwareInterface>
    </joint>
    <actuator name="act_1">
      <hardwareInterface>EffortJointInterface</hardwareInterface>
      <mechanicalReduction>1</mechanicalReduction>
    </actuator>
  </transmission>
  <transmission name="trans_2">
    <type>transmission_interface/SimpleTransmission</type>
    <joint name="move_2_joint">
      <hardwareInterface>EffortJointInterface</hardwareInterface>
    </joint>
    <actuator name="act_2">
      <hardwareInterface>EffortJointInterface</hardwareInterface>
      <mechanicalReduction>1</mechanicalReduction>
    </actuator>
  </transmission>
  <transmission name="trans_3">
    <type>transmission_interface/SimpleTransmission</type>
    <joint name="move_3_joint">
      <hardwareInterface>EffortJointInterface</hardwareInterface>
    </joint>
    <actuator name="act_3">
      <hardwareInterface>EffortJointInterface</hardwareInterface>
      <mechanicalReduction>1</mechanicalReduction>
    </actuator>
  </transmission>
  <!--
  Author: Kelsey Hawkins 
  Contributers: Jimmy Da Silva, Ajit Krisshna N L, Muhammad Asif Rana 
-->
  <!-- measured from model -->
  <link name="ur_base_link">
    <visual>
      <geometry>
        <mesh filename="package://ur_description/meshes/ur10/visual/base.dae"/>
      </geometry>
      <material name="LightGrey">
        <color rgba="0.7 0.7 0.7 1.0"/>
      </material>
    </visual>
    <collision>
      <geometry>
        <mesh filename="package://ur_description/meshes/ur10/collision/base.stl"/>
      </geometry>
    </collision>
    <inertial>
      <mass value="4.0"/>
      <origin rpy="0 0 0" xyz="0.0 0.0 0.0"/>
      <inertia ixx="0.0061063308908" ixy="0.0" ixz="0.0" iyy="0.0061063308908" iyz="0.0" izz="0.01125"/>
    </inertial>
  </link>
  <joint name="ur_shoulder_pan_joint" type="revolute">
    <parent link="ur_base_link"/>
    <child link="ur_shoulder_link"/>
    <origin rpy="0.0 0.0 0.0" xyz="0.0 0.0 0.1273"/>
    <axis xyz="0 0 1"/>
    <limit effort="330.0" lower="-6.2831853" upper="6.2831853" velocity="2.16"/>
    <dynamics damping="0.0" friction="0.0"/>
  </joint>
  <link name="ur_shoulder_link">
    <visual>
      <geometry>
        <mesh filename="package://ur_description/meshes/ur10/visual/shoulder.dae"/>
      </geometry>
      <material name="LightGrey">
        <color rgba="0.7 0.7 0.7 1.0"/>
      </material>
    </visual>
    <collision>
      <geometry>
        <mesh filename="package://ur_description/meshes/ur10/collision/shoulder.stl"/>
      </geometry>
    </collision>
    <inertial>
      <mass value="7.778"/>
      <origin rpy="0 0 0" xyz="0.0 0.0 0.0"/>
      <inertia ixx="0.0314743125769" ixy="0.0" ixz="0.0" iyy="0.0314743125769" iyz="0.0" izz="0.021875625"/>
    </inertial>
  </link>
  <joint name="ur_shoulder_lift_joint" type="revolute">
    <parent link="ur_shoulder_link"/>
    <child link="ur_upper_arm_link"/>
    <origin rpy="0.0 1.570796325 0.0" xyz="0.0 0.220941 0.0"/>
    <axis xyz="0 1 0"/>
    <limit effort="330.0" lower="-6.2831853" upper="6.2831853" velocity="2.16"/>
    <dynamics damping="0.0" friction="0.0"/>
  </joint>
  <link name="ur_upper_arm_link">
    <visual>
      <geometry>
        <mesh filename="package://ur_description/meshes/ur10/visual/upperarm.dae"/>
      </geometry>
      <material name="LightGrey">
        <color rgba="0.7 0.7 0.7 1.0"/>
      </material>
    </visual>
    <collision>
      <geometry>
        <mesh filename="package://ur_description/meshes/ur10/collision/upperarm.stl"/>
      </geometry>
    </collision>
    <inertial>
      <mass value="12.93"/>
      <origin rpy="0 0 0" xyz="0.0 0.0 0.306"/>
      <inertia ixx="0.421753803798" ixy="0.0" ixz="0.0" iyy="0.421753803798" iyz="0.0" izz="0.036365625"/>
    </inertial>
  </link>
  <joint name="ur_elbow_joint" type="revolute">
    <parent link="ur_upper_arm_link"/>
    <child link="ur_forearm_link"/>
    <origin rpy="0.0 0.0 0.0" xyz="0.0 -0.1719 0.612"/>
    <axis xyz="0 1 0"/>
    <limit effort="150.0" lower="-6.2831853" upper="6.2831853" velocity="3.15"/>
    <dynamics damping="0.0" friction="0.0"/>
  </joint>
  <link name="ur_forearm_link">
    <visual>
      <geometry>
        <mesh filename="package://ur_description/meshes/ur10/visual/forearm.dae"/>
      </geometry>
      <material name="LightGrey">
        <color rgba="0.7 0.7 0.7 1.0"/>
      </material>
    </visual>
    <collision>
      <geometry>
        <mesh filename="package://ur_description/meshes/ur10/collision/forearm.stl"/>
      </geometry>
    </collision>
    <inertial>
      <mass value="3.87"/>
      <origin rpy="0 0 0" xyz="0.0 0.0 0.28615"/>
      <inertia ixx="0.111069694097" ixy="0.0" ixz="0.0" iyy="0.111069694097" iyz="0.0" izz="0.010884375"/>
    </inertial>
  </link>
  <joint name="ur_wrist_1_joint" type="revolute">
    <parent link="ur_forearm_link"/>
    <child link="ur_wrist_1_link"/>
    <origin rpy="0.0 1.570796325 0.0" xyz="0.0 0.0 0.5723"/>
    <axis xyz="0 1 0"/>
    <limit effort="54.0" lower="-6.2831853" upper="6.2831853" velocity="3.2"/>
    <dynamics damping="0.0" friction="0.0"/>
  </joint>
  <link name="ur_wrist_1_link">
    <visual>
      <geometry>
        <mesh filename="package://ur_description/meshes/ur10/visual/wrist1.dae"/>
      </geometry>
      <material name="LightGrey">
        <color rgba="0.7 0.7 0.7 1.0"/>
      </material>
    </visual>
    <collision>
      <geometry>
        <mesh filename="package://ur_description/meshes/ur10/collision/wrist1.stl"/>
      </geometry>
    </collision>
    <inertial>
      <mass value="1.96"/>
      <origin rpy="0 0 0" xyz="0.0 0.0 0.0"/>
      <inertia ixx="0.0051082479567" ixy="0.0" ixz="0.0" iyy="0.0051082479567" iyz="0.0" izz="0.0055125"/>
    </inertial>
  </link>
  <joint name="ur_wrist_2_joint" type="revolute">
    <parent link="ur_wrist_1_link"/>
    <child link="ur_wrist_2_link"/>
    <origin rpy="0.0 0.0 0.0" xyz="0.0 0.1149 0.0"/>
    <axis xyz="0 0 1"/>
    <limit effort="54.0" lower="-6.2831853" upper="6.2831853" velocity="3.2"/>
    <dynamics damping="0.0" friction="0.0"/>
  </joint>
  <link name="ur_wrist_2_link">
    <visual>
      <geometry>
        <mesh filename="package://ur_description/meshes/ur10/visual/wrist2.dae"/>
      </geometry>
      <material name="LightGrey">
        <color rgba="0.7 0.7 0.7 1.0"/>
      </material>
    </visual>
    <collision>
      <geometry>
        <mesh filename="package://ur_description/meshes/ur10/collision/wrist2.stl"/>
      </geometry>
    </collision>
    <inertial>
      <mass value="1.96"/>
      <origin rpy="0 0 0" xyz="0.0 0.0 0.0"/>
      <inertia ixx="0.0051082479567" ixy="0.0" ixz="0.0" iyy="0.0051082479567" iyz="0.0" izz="0.0055125"/>
    </inertial>
  </link>
  <joint name="ur_wrist_3_joint" type="revolute">
    <parent link="ur_wrist_2_link"/>
    <child link="ur_wrist_3_link"/>
    <origin rpy="0.0 0.0 0.0" xyz="0.0 0.0 0.1157"/>
    <axis xyz="0 1 0"/>
    <limit effort="54.0" lower="-6.2831853" upper="6.2831853" velocity="3.2"/>
    <dynamics damping="0.0" friction="0.0"/>
  </joint>
  <link name="ur_wrist_3_link">
    <visual>
      <geometry>
        <mesh filename="package://ur_description/meshes/ur10/visual/wrist3.dae"/>
      </geometry>
      <material name="LightGrey">
        <color rgba="0.7 0.7 0.7 1.0"/>
      </material>
    </visual>
    <collision>
      <geometry>
        <mesh filename="package://ur_description/meshes/ur10/collision/wrist3.stl"/>
      </geometry>
    </collision>
    <inertial>
      <mass value="0.202"/>
      <origin rpy="0 0 0" xyz="0.0 0.0 0.0"/>
      <inertia ixx="0.000526462289415" ixy="0.0" ixz="0.0" iyy="0.000526462289415" iyz="0.0" izz="0.000568125"/>
    </inertial>
  </link>
  <joint name="ur_ee_fixed_joint" type="fixed">
    <parent link="ur_wrist_3_link"/>
    <child link="ur_ee_link"/>
    <origin rpy="0.0 0.0 1.570796325" xyz="0.0 0.0922 0.0"/>
  </joint>
  <link name="ur_ee_link">
    <collision>
      <geometry>
        <box size="0.01 0.01 0.01"/>
      </geometry>
      <origin rpy="0 0 0" xyz="-0.01 0 0"/>
    </collision>
  </link>
  <transmission name="ur_shoulder_pan_trans">
    <type>transmission_interface/SimpleTransmission</type>
    <joint name="ur_shoulder_pan_joint">
      <hardwareInterface>PositionJointInterface</hardwareInterface>
    </joint>
    <actuator name="ur_shoulder_pan_motor">
      <mechanicalReduction>1</mechanicalReduction>
    </actuator>
  </transmission>
  <transmission name="ur_shoulder_lift_trans">
    <type>transmission_interface/SimpleTransmission</type>
    <joint name="ur_shoulder_lift_joint">
      <hardwareInterface>PositionJointInterface</hardwareInterface>
    </joint>
    <actuator name="ur_shoulder_lift_motor">
      <mechanicalReduction>1</mechanicalReduction>
    </actuator>
  </transmission>
  <transmission name="ur_elbow_trans">
    <type>transmission_interface/SimpleTransmission</type>
    <joint name="ur_elbow_joint">
      <hardwareInterface>PositionJointInterface</hardwareInterface>
    </joint>
    <actuator name="ur_elbow_motor">
      <mechanicalReduction>1</mechanicalReduction>
    </actuator>
  </transmission>
  <transmission name="ur_wrist_1_trans">
    <type>transmission_interface/SimpleTransmission</type>
    <joint name="ur_wrist_1_joint">
      <hardwareInterface>PositionJointInterface</hardwareInterface>
    </joint>
    <actuator name="ur_wrist_1_motor">
      <mechanicalReduction>1</mechanicalReduction>
    </actuator>
  </transmission>
  <transmission name="ur_wrist_2_trans">
    <type>transmission_interface/SimpleTransmission</type>
    <joint name="ur_wrist_2_joint">
      <hardwareInterface>PositionJointInterface</hardwareInterface>
    </joint>
    <actuator name="ur_wrist_2_motor">
      <mechanicalReduction>1</mechanicalReduction>
    </actuator>
  </transmission>
  <transmission name="ur_wrist_3_trans">
    <type>transmission_interface/SimpleTransmission</type>
    <joint name="ur_wrist_3_joint">
      <hardwareInterface>PositionJointInterface</hardwareInterface>
    </joint>
    <actuator name="ur_wrist_3_motor">
      <mechanicalReduction>1</mechanicalReduction>
    </actuator>
  </transmission>
  <!-- nothing to do here at the moment -->
  <!-- ROS base_link to UR 'Base' Coordinates transform -->
  <link name="ur_base"/>
  <joint name="ur_base_link-base_fixed_joint" type="fixed">
    <!-- NOTE: this rotation is only needed as long as base_link itself is
                 not corrected wrt the real robot (ie: rotated over 180
                 degrees)
      -->
    <origin rpy="0 0 -3.14159265" xyz="0 0 0"/>
    <parent link="ur_base_link"/>
    <child link="ur_base"/>
  </joint>
  <!-- Frame coincident with all-zeros TCP on UR controller -->
  <link name="ur_tool0"/>
  <joint name="ur_wrist_3_link-tool0_fixed_joint" type="fixed">
    <origin rpy="-1.570796325 0 0" xyz="0 0.0922 0"/>
    <parent link="ur_wrist_3_link"/>
    <child link="ur_tool0"/>
  </joint>
  <!-- Create stereo_basler model -->
  <link name="stereo_basler">
    <visual>
      <origin rpy="1.570795 0 3.14159" xyz="0 -0.015 -0.015"/>
      <geometry>
        <mesh filename="package://pingpang_gazebo/urdf/meshes/basler.stl"/>
      </geometry>
      <material name="LightGrey">
        <color rgba="0.7 0.7 0.7 1.0"/>
      </material>
    </visual>
    <collision>
      <origin rpy="1.570795 0 3.14159" xyz="0 -0.015 -0.015"/>
      <geometry>
        <mesh filename="package://pingpang_gazebo/urdf/meshes/basler.stl"/>
      </geometry>
      <material name="LightGrey">
        <color rgba="0.7 0.7 0.7 1.0"/>
      </material>
    </collision>
    <inertial>
      <mass value="1e-5"/>
      <origin rpy="0 0 0" xyz="0 0 0"/>
      <inertia ixx="1e-6" ixy="0" ixz="0" iyy="1e-6" iyz="0" izz="1e-6"/>
    </inertial>
  </link>
  <joint name="basler_basler_l_to_basler_r" type="fixed">
    <parent link="stereo_basler"/>
    <child link="basler_basler_r"/>
  </joint>
  <link name="basler_basler_r">
    <visual>
      <origin rpy="1.570795 0 3.14159" xyz="0 -0.155 -0.015"/>
      <geometry>
        <mesh filename="package://pingpang_gazebo/urdf/meshes/basler.stl"/>
      </geometry>
      <material name="LightGrey">
        <color rgba="0.7 0.7 0.7 1.0"/>
      </material>
    </visual>
    <collision>
      <origin rpy="1.570795 0 3.14159" xyz="0 -0.155 -0.015"/>
      <geometry>
        <mesh filename="package://pingpang_gazebo/urdf/meshes/basler.stl"/>
      </geometry>
      <material name="LightGrey">
        <color rgba="0.7 0.7 0.7 1.0"/>
      </material>
    </collision>
    <inertial>
      <mass value="1e-5"/>
      <origin rpy="0 0 0" xyz="0 0 0"/>
      <inertia ixx="1e-6" ixy="0" ixz="0" iyy="1e-6" iyz="0" izz="1e-6"/>
    </inertial>
  </link>
  <!--optical position parameter-->
  <joint name="basler_optical_joint" type="fixed">
    <origin rpy="0 0 0" xyz="0 0 0"/>
    <parent link="stereo_basler"/>
    <child link="basler_frame_optical"/>
  </joint>
  <link name="basler_frame_optical"/>
  <!--camera sensor parameter-->
  <gazebo reference="basler_frame_optical">
    <sensor name="basler_stereo_camera" type="multicamera">
      <update_rate>30.0</update_rate>
      <camera name="left">
        <pose>0 0 0 0 0 0</pose>
        <!--pose>0 0.155 0 0 0 0</pose-->
        <horizontal_fov>1.57079633</horizontal_fov>
        <image>
          <width>640</width>
          <height>480</height>
          <format>R8G8B8</format>
        </image>
        <clip>
          <near>0.02</near>
          <far>30</far>
        </clip>
        <noise>
          <type>gaussian</type>
          <mean>0.0</mean>
          <stddev>0.007</stddev>
        </noise>
      </camera>
      <camera name="right">
        <pose>0 -0.14 0 0 0 0</pose>
        <!--pose>0 0.548 0 3.14 0 0</pose-->
        <horizontal_fov>1.57079633</horizontal_fov>
        <image>
          <width>640</width>
          <height>480</height>
          <format>R8G8B8</format>
        </image>
        <clip>
          <near>0.02</near>
          <far>300</far>
        </clip>
        <noise>
          <type>gaussian</type>
          <mean>0.0</mean>
          <stddev>0.007</stddev>
        </noise>
      </camera>
      <plugin filename="libgazebo_ros_multicamera.so" name="stereo_camera_controller">
        <alwaysOn>true</alwaysOn>
        <updateRate>0.0</updateRate>
        <!--cameraName>multisense_sl/camera</cameraName-->
        <cameraName>multi/camera/basler</cameraName>
        <imageTopicName>image_raw</imageTopicName>
        <cameraInfoTopicName>camera_info</cameraInfoTopicName>
        <frameName>basler_frame_optical</frameName>
        <!--<rightFrameName>${prefix}_frame_optical</rightFrameName>-->
        <foclLength>320.000101</foclLength>
        <hackBaseline>0.14</hackBaseline>
        <distortionK1>0</distortionK1>
        <distortionK2>0</distortionK2>
        <distortionK3>0</distortionK3>
        <distortionT1>0</distortionT1>
        <distortionT2>0</distortionT2>
      </plugin>
    </sensor>
  </gazebo>
  <!-- stereo_camera1_frame_joint -->
  <joint name="stereo_camera_frame_joint" type="fixed">
    <origin rpy="0 0 0" xyz="0.05 0.07 0.015"/>
    <parent link="base_link"/>
    <child link="stereo_basler"/>
  </joint>
  <link name="world"/>
  <joint name="world_joint_1" type="fixed">
    <parent link="world"/>
    <child link="ur_base_link"/>
    <origin rpy="0.0 0.0 0.0" xyz="1.0 1.0 1.0"/>
  </joint>
  <link name="base_link">
    <visual>
      <geometry>
        <box size="0.1 0.1 0.01"/>
      </geometry>
    </visual>
    <collision>
      <geometry>
        <box size="0.1 0.1 0.01"/>
      </geometry>
    </collision>
    <inertial>
      <mass value="0.1"/>
      <inertia ixx="0.1" ixy="0.0" ixz="0.0" iyy="0.1" iyz="0.0" izz="0.1"/>
    </inertial>
  </link>
  <joint name="world_joint" type="fixed">
    <origin rpy="0 0.19634954125 -1.57079633" xyz="0.8 3 1.5"/>
    <parent link="world"/>
    <child link="base_link"/>
  </joint>
  <link name="move_link">
    <visual>
      <geometry>
        <box size="2 0.5 0.6"/>
      </geometry>
    </visual>
    <collision>
      <geometry>
        <box size="2 0.5 0.6"/>
      </geometry>
    </collision>
    <inertial>
      <mass value="0.1"/>
      <inertia ixx="0.1" ixy="0.0" ixz="0.0" iyy="0.1" iyz="0.0" izz="0.1"/>
    </inertial>
  </link>
  <joint name="move_joint" type="fixed">
    <origin rpy="0 0 0" xyz="0.8 3 0.3"/>
    <parent link="world"/>
    <child link="move_link"/>
  </joint>
  <link name="move_1_link">
    <visual>
      <geometry>
        <box size="0.02 0.02 0.6"/>
      </geometry>
      <material name="body"/>
    </visual>
    <collision>
      <geometry>
        <box size="0.02 0.02 0.6"/>
      </geometry>
    </collision>
    <inertial>
      <mass value="0.1"/>
      <inertia ixx="0.1" ixy="0.0" ixz="0.0" iyy="0.1" iyz="0.0" izz="0.1"/>
    </inertial>
  </link>
  <joint name="move_1_joint" type="prismatic">
    <origin rpy="0 0 0" xyz="0 0 0.6"/>
    <axis xyz="1 0 0"/>
    <parent link="move_link"/>
    <child link="move_1_link"/>
    <limit effort="1000.0" lower="-3" upper="3" velocity="0.5"/>
  </joint>
  <link name="move_2_link">
    <visual>
      <geometry>
        <box size="0.02 0.02 0.2"/>
      </geometry>
      <material name="body"/>
    </visual>
    <collision>
      <geometry>
        <box size="0.02 0.02 0.2"/>
      </geometry>
    </collision>
    <inertial>
      <mass value="0.1"/>
      <inertia ixx="0.1" ixy="0.0" ixz="0.0" iyy="0.1" iyz="0.0" izz="0.1"/>
    </inertial>
  </link>
  <joint name="move_2_joint" type="prismatic">
    <origin rpy="0 1.57079633 0" xyz="0 -0.02 0"/>
    <axis xyz="1 0 0"/>
    <parent link="move_1_link"/>
    <child link="move_2_link"/>
    <limit effort="1000.0" lower="-0.2" upper="0.2" velocity="0.5"/>
  </joint>
  <link name="move_3_link">
    <visual>
      <geometry>
        <box size="0.2 0.01 0.2"/>
      </geometry>
      <material name="body"/>
    </visual>
    <collision>
      <geometry>
        <box size="0.2 0.01 0.2"/>
      </geometry>
    </collision>
    <inertial>
      <mass value="0.1"/>
      <inertia ixx="0.1" ixy="0.0" ixz="0.0" iyy="0.1" iyz="0.0" izz="0.1"/>
    </inertial>
  </link>
  <joint name="move_3_joint" type="prismatic">
    <origin rpy="0 0 0" xyz="0 -0.015 0"/>
    <axis xyz="0 1 0"/>
    <parent link="move_2_link"/>
    <child link="move_3_link"/>
    <limit effort="1000.0" lower="-3" upper="3" velocity="0.5"/>
  </joint>
  <gazebo reference="move_1_link">
    <material>Gazebo/Red</material>
  </gazebo>
  <gazebo reference="move_2_link">
    <material>Gazebo/Blue</material>
  </gazebo>
  <gazebo reference="move_3_link">
    <material>Gazebo/Red</material>
  </gazebo>
  <gazebo>
    <plugin filename="libgazebo_ros_control.so" name="gazebo_ros_control">
      <controlPeriod>0.001</controlPeriod>
    </plugin>
  </gazebo>
</robot>
